Traceback (most recent call last):
  File "C:\Users\haldo\AppData\Local\Programs\Python\Python313\Lib\site-packages\jupyter_core\utils\__init__.py", line 154, in wrapped
    asyncio.get_running_loop()
    ~~~~~~~~~~~~~~~~~~~~~~~~^^
RuntimeError: no running event loop

During handling of the above exception, another exception occurred:

Traceback (most recent call last):
  File "C:\Users\haldo\AppData\Local\Programs\Python\Python313\Lib\site-packages\jupyter_cache\executors\utils.py", line 58, in single_nb_execution
    executenb(
    ~~~~~~~~~^
        nb,
        ^^^
    ...<4 lines>...
        **kwargs,
        ^^^^^^^^^
    )
    ^
  File "C:\Users\haldo\AppData\Local\Programs\Python\Python313\Lib\site-packages\nbclient\client.py", line 1319, in execute
    return NotebookClient(nb=nb, resources=resources, km=km, **kwargs).execute()
           ~~~~~~~~~~~~~~~~~~~~~~~~~~~~~~~~~~~~~~~~~~~~~~~~~~~~~~~~~~~~~~~~~~~^^
  File "C:\Users\haldo\AppData\Local\Programs\Python\Python313\Lib\site-packages\jupyter_core\utils\__init__.py", line 158, in wrapped
    return loop.run_until_complete(inner)
           ~~~~~~~~~~~~~~~~~~~~~~~^^^^^^^
  File "C:\Users\haldo\AppData\Local\Programs\Python\Python313\Lib\asyncio\base_events.py", line 725, in run_until_complete
    return future.result()
           ~~~~~~~~~~~~~^^
  File "C:\Users\haldo\AppData\Local\Programs\Python\Python313\Lib\site-packages\nbclient\client.py", line 709, in async_execute
    await self.async_execute_cell(
        cell, index, execution_count=self.code_cells_executed + 1
    )
  File "C:\Users\haldo\AppData\Local\Programs\Python\Python313\Lib\site-packages\nbclient\client.py", line 1062, in async_execute_cell
    await self._check_raise_for_error(cell, cell_index, exec_reply)
  File "C:\Users\haldo\AppData\Local\Programs\Python\Python313\Lib\site-packages\nbclient\client.py", line 918, in _check_raise_for_error
    raise CellExecutionError.from_cell_and_msg(cell, exec_reply_content)
nbclient.exceptions.CellExecutionError: An error occurred while executing the following cell:
------------------
import pandas as pd

# 1. Load datasets
co2 = pd.read_csv('owid-co2-data.csv')
hale = pd.read_csv('C64284D_ALL_LATEST.csv')

# 2. Select years & fields
years = [2000, 2010, 2015, 2019, 2021]
co2_sel = co2[co2['year'].isin(years)][['iso_code','country','year','co2_per_capita','cumulative_co2']].copy()
hale_sel = (hale[hale['Year'].isin(years)]
            [['Country','Year','Healthy_life_expectancy_at_birth']]
            .rename(columns={'Country':'country','Year':'year','Healthy_life_expectancy_at_birth':'healthy_life_expectancy'})
            .copy())

# 3. Exclude aggregates
aggregates = ['World','Asia','Europe','Africa','North America','South America','Oceania','European Union (27)']
co2_clean = co2_sel[~co2_sel['country'].isin(aggregates)]
hale_clean = hale_sel[~hale_sel['country'].isin(aggregates)]

# 4. Merge and clean
merged_df = pd.merge(co2_clean, hale_clean, on=['country','year'], how='inner').dropna()

# 5. Calculate COâ‚‚ Intensity
merged_df['co2_intensity'] = merged_df['co2_per_capita'] / merged_df['healthy_life_expectancy']

# 6. Inspect
merged_df.head()
------------------


[31m---------------------------------------------------------------------------[39m
[31mModuleNotFoundError[39m                       Traceback (most recent call last)
[36mCell[39m[36m [39m[32mIn[1][39m[32m, line 1[39m
[32m----> [39m[32m1[39m [38;5;28;01mimport[39;00m[38;5;250m [39m[34;01mpandas[39;00m[38;5;250m [39m[38;5;28;01mas[39;00m[38;5;250m [39m[34;01mpd[39;00m
[32m      3[39m [38;5;66;03m# 1. Load datasets[39;00m
[32m      4[39m co2 = pd.read_csv([33m'[39m[33mowid-co2-data.csv[39m[33m'[39m)

[31mModuleNotFoundError[39m: No module named 'pandas'

