Traceback (most recent call last):
  File "C:\Users\haldo\AppData\Local\Programs\Python\Python313\Lib\site-packages\jupyter_core\utils\__init__.py", line 154, in wrapped
    asyncio.get_running_loop()
    ~~~~~~~~~~~~~~~~~~~~~~~~^^
RuntimeError: no running event loop

During handling of the above exception, another exception occurred:

Traceback (most recent call last):
  File "C:\Users\haldo\AppData\Local\Programs\Python\Python313\Lib\site-packages\jupyter_cache\executors\utils.py", line 58, in single_nb_execution
    executenb(
    ~~~~~~~~~^
        nb,
        ^^^
    ...<4 lines>...
        **kwargs,
        ^^^^^^^^^
    )
    ^
  File "C:\Users\haldo\AppData\Local\Programs\Python\Python313\Lib\site-packages\nbclient\client.py", line 1319, in execute
    return NotebookClient(nb=nb, resources=resources, km=km, **kwargs).execute()
           ~~~~~~~~~~~~~~~~~~~~~~~~~~~~~~~~~~~~~~~~~~~~~~~~~~~~~~~~~~~~~~~~~~~^^
  File "C:\Users\haldo\AppData\Local\Programs\Python\Python313\Lib\site-packages\jupyter_core\utils\__init__.py", line 158, in wrapped
    return loop.run_until_complete(inner)
           ~~~~~~~~~~~~~~~~~~~~~~~^^^^^^^
  File "C:\Users\haldo\AppData\Local\Programs\Python\Python313\Lib\asyncio\base_events.py", line 725, in run_until_complete
    return future.result()
           ~~~~~~~~~~~~~^^
  File "C:\Users\haldo\AppData\Local\Programs\Python\Python313\Lib\site-packages\nbclient\client.py", line 709, in async_execute
    await self.async_execute_cell(
        cell, index, execution_count=self.code_cells_executed + 1
    )
  File "C:\Users\haldo\AppData\Local\Programs\Python\Python313\Lib\site-packages\nbclient\client.py", line 1062, in async_execute_cell
    await self._check_raise_for_error(cell, cell_index, exec_reply)
  File "C:\Users\haldo\AppData\Local\Programs\Python\Python313\Lib\site-packages\nbclient\client.py", line 918, in _check_raise_for_error
    raise CellExecutionError.from_cell_and_msg(cell, exec_reply_content)
nbclient.exceptions.CellExecutionError: An error occurred while executing the following cell:
------------------
import plotly.express as px

# World map with CO2 per capita and Healthy Life Expectancy
fig = px.scatter_geo(
    merged_df[merged_df['year'] == 2019],
    locations='iso_code',
    color='healthy_life_expectancy_at_birth',
    size='co2_per_capita',
    color_continuous_scale='Viridis',
    hover_name='country',
    title='Healthy Life Expectancy (color) and COâ‚‚ Emissions per Capita (size) in 2019'
)

fig.show()

------------------


[31m---------------------------------------------------------------------------[39m
[31mNameError[39m                                 Traceback (most recent call last)
[36mCell[39m[36m [39m[32mIn[4][39m[32m, line 5[39m
[32m      1[39m [38;5;28;01mimport[39;00m[38;5;250m [39m[34;01mplotly[39;00m[34;01m.[39;00m[34;01mexpress[39;00m[38;5;250m [39m[38;5;28;01mas[39;00m[38;5;250m [39m[34;01mpx[39;00m
[32m      3[39m [38;5;66;03m# World map with CO2 per capita and Healthy Life Expectancy[39;00m
[32m      4[39m fig = px.scatter_geo(
[32m----> [39m[32m5[39m     [43mmerged_df[49m[merged_df[[33m'[39m[33myear[39m[33m'[39m] == [32m2019[39m],
[32m      6[39m     locations=[33m'[39m[33miso_code[39m[33m'[39m,
[32m      7[39m     color=[33m'[39m[33mhealthy_life_expectancy_at_birth[39m[33m'[39m,
[32m      8[39m     size=[33m'[39m[33mco2_per_capita[39m[33m'[39m,
[32m      9[39m     color_continuous_scale=[33m'[39m[33mViridis[39m[33m'[39m,
[32m     10[39m     hover_name=[33m'[39m[33mcountry[39m[33m'[39m,
[32m     11[39m     title=[33m'[39m[33mHealthy Life Expectancy (color) and COâ‚‚ Emissions per Capita (size) in 2019[39m[33m'[39m
[32m     12[39m )
[32m     14[39m fig.show()

[31mNameError[39m: name 'merged_df' is not defined

